<?xml version="1.0" encoding="utf-8"?>
<!-- =================================================================================== -->
<!-- |    This document was autogenerated by xacro from ur5_robot.urdf.xacro           | -->
<!-- |    EDITING THIS FILE BY HAND IS NOT RECOMMENDED                                 | -->
<!-- =================================================================================== -->
<robot name="combined">
  <!--robots pose-->
  <link name="world"/>

  
  <joint name="UR1_pose" type="fixed">
    <parent link="world"/>
    <child link="UR1_pedestal"/>
    <origin rpy="0.0 0.0 1.57" xyz="1.2 0 0.0"/><!--ur pedestal-->
  </joint>

  <joint name="UR2_pose" type="fixed">
    <parent link="world"/>
    <child link="UR2_pedestal"/>
    <origin rpy="0.0 0.0 1.57" xyz="1.2 0 0.0"/><!--ur pedestal-->
  </joint>

  <joint name="UR3_pose" type="fixed">
    <parent link="world"/>
    <child link="UR3_pedestal"/>
    <origin rpy="0.0 0.0 1.57" xyz="1.2 0 0.0"/><!--ur pedestal-->
  </joint>

  <joint name="UR4_pose" type="fixed">
    <parent link="world"/>
    <child link="UR4_pedestal"/>
    <origin rpy="0.0 0.0 1.57" xyz="1.2 0 0.0"/><!--ur pedestal-->
  </joint>

  <joint name="ABB1_pose" type="fixed">
    <parent link="world"/>
    <child link="ABB1_pedestal"/>
    <origin rpy="0.0 0.0 0.0" xyz="0 1.2 0.0"/><!--abb pedestal-->
  </joint>

  <joint name="ABB2_pose" type="fixed">
    <parent link="world"/>
    <child link="ABB2_pedestal"/>
    <origin rpy="0.0 0.0 0.0" xyz="0 1.2 0.0"/><!--abb pedestal-->
  </joint>

  <joint name="ABB3_pose" type="fixed">
    <parent link="world"/>
    <child link="ABB3_pedestal"/>
    <origin rpy="0.0 0.0 0.0" xyz="0 1.2 0.0"/><!--abb pedestal-->
  </joint>

  <joint name="ABB4_pose" type="fixed">
    <parent link="world"/>
    <child link="ABB4_pedestal"/>
    <origin rpy="0.0 0.0 0.0" xyz="0 1.2 0.0"/><!--abb pedestal-->
  </joint>

  <!--UR part-->
  <joint name="UR1_elbow_joint" type="revolute">
    <parent link="UR1_upper_arm_link"/>
    <child link="UR1_forearm_link"/>
    <origin rpy="0 0 0" xyz="0     -0.1197  0.425"/>
    <axis xyz="0 1 0"/>
    <limit effort="150.0" lower="-3.14159" upper="3.14159" velocity="3.15"/>
  </joint>
  <joint name="UR1_pedestal_JOINT_1" type="fixed">
    <parent link="UR1_pedestal"/>
    <child link="UR1_base_link"/>
    <origin rpy="0 0 0" xyz="0 0 0"/>
    <axis xyz="0 0 0"/>
    <limit effort="0" lower="0" upper="0" velocity="0"/>
  </joint>
  <joint name="UR1_shoulder_lift_joint" type="revolute">
    <parent link="UR1_shoulder_link"/>
    <child link="UR1_upper_arm_link"/>
    <origin rpy="3.14148 1.57079 3.14148" xyz="0      0.13585 0"/>
    <axis xyz="0 1 0"/>
    <limit effort="150.0" lower="-6.28319" upper="6.28319" velocity="3.15"/>
  </joint>
  <joint name="UR1_shoulder_pan_joint" type="revolute">
    <parent link="UR1_base_link"/>
    <child link="UR1_shoulder_link"/>
    <origin rpy="0 0 0" xyz="0      0      0.08915"/>
    <axis xyz="0 0 1"/>
    <limit effort="150.0" lower="-6.28319" upper="6.28319" velocity="3.15"/>
  </joint>
  <joint name="UR1_wrist_1_joint" type="revolute">
    <parent link="UR1_forearm_link"/>
    <child link="UR1_wrist_1_link"/>
    <origin rpy="0.39713 1.57078 0.39713" xyz="0      0      0.39225"/>
    <axis xyz="0 1 0"/>
    <limit effort="28.0" lower="-6.28319" upper="6.28319" velocity="3.2"/>
  </joint>
  <joint name="UR1_wrist_2_joint" type="revolute">
    <parent link="UR1_wrist_1_link"/>
    <child link="UR1_wrist_2_link"/>
    <origin rpy="0 0 0" xyz="0    0.093 0"/>
    <axis xyz="0 0 1"/>
    <limit effort="28.0" lower="-6.28319" upper="6.28319" velocity="3.2"/>
  </joint>
  <joint name="UR1_wrist_3_joint" type="revolute">
    <parent link="UR1_wrist_2_link"/>
    <child link="UR1_wrist_3_link"/>
    <origin rpy="0 0 0" xyz="0      0      0.09465"/>
    <axis xyz="0 1 0"/>
    <limit effort="28.0" lower="-6.28319" upper="6.28319" velocity="3.2"/>
  </joint>
  <link name="UR1_base_link">
    <inertial>
      <mass value="4"/>
      <origin rpy="0 0 0" xyz="0 0 0"/>
      <inertia ixx="0.00443333" ixy="0" ixz="0" iyy="0.00443333" iyz="0" izz="0.0072"/>
    </inertial>
    <collision name="UR1_base_link_collision">
      <origin rpy="0 0 0" xyz="0 0 0"/>
      <geometry>
        <mesh filename="model://ur5/meshes/ur5/collision/base.stl" scale="1 1 1"/>
      </geometry>
    </collision>
    <visual name="UR1_base_link_visual">
      <origin rpy="0 0 0" xyz="0 0 0"/>
      <geometry>
        <mesh filename="model://ur5/meshes/ur5/visual/base.dae" scale="1 1 1"/>
      </geometry>
    </visual>
  </link>
  <link name="UR1_forearm_link">
    <inertial>
      <mass value="2.275"/>
      <origin rpy="0 0 0" xyz="0   0   0.25"/>
      <inertia ixx="0.0494433" ixy="0" ixz="0" iyy="0.0494433" iyz="0" izz="0.004095"/>
    </inertial>
    <collision name="UR1_forearm_link_collision">
      <origin rpy="0 0 0" xyz="0 0 0"/>
      <geometry>
        <mesh filename="model://ur5/meshes/ur5/collision/forearm.stl" scale="1 1 1"/>
      </geometry>
    </collision>
    <visual name="UR1_forearm_link_visual">
      <origin rpy="0 0 0" xyz="0 0 0"/>
      <geometry>
        <mesh filename="model://ur5/meshes/ur5/visual/forearm.dae" scale="1 1 1"/>
      </geometry>
    </visual>
  </link>
  <link name="UR1_pedestal">
    <inertial>
      <mass value="1"/>
      <origin rpy="0 0 0" xyz="0 0 0"/>
      <inertia ixx="0.145833" ixy="0" ixz="0" iyy="0.145833" iyz="0" izz="0.125"/>
    </inertial>
<!--     <collision name="UR1_collision">
      <origin rpy="-2.0e-05  1.4e-04  0.0e+00" xyz="0   0  -0.5"/>
      <geometry>
        <cylinder length="1" radius="0.15"/>
      </geometry>
    </collision> -->
    <visual name="UR1_visual">
      <origin rpy="-2.0e-05  1.4e-04  0.0e+00" xyz="0   0  -0.5"/>
      <geometry>
        <cylinder length="1" radius="0.15"/>
      </geometry>
    </visual>
  </link>
  <link name="UR1_shoulder_link">
    <inertial>
      <mass value="3.7"/>
      <origin rpy="0 0 0" xyz="0 0 0"/>
      <inertia ixx="0.0102675" ixy="0" ixz="0" iyy="0.0102675" iyz="0" izz="0.00666"/>
    </inertial>
    <collision name="UR1_shoulder_link_collision">
      <origin rpy="0 0 0" xyz="0 0 0"/>
      <geometry>
        <mesh filename="model://ur5/meshes/ur5/collision/shoulder.stl" scale="1 1 1"/>
      </geometry>
    </collision>
    <visual name="UR1_shoulder_link_visual">
      <origin rpy="0 0 0" xyz="0 0 0"/>
      <geometry>
        <mesh filename="model://ur5/meshes/ur5/visual/shoulder.dae" scale="1 1 1"/>
      </geometry>
    </visual>
  </link>
  <link name="UR1_upper_arm_link">
    <inertial>
      <mass value="8.393"/>
      <origin rpy="0 0 0" xyz="0   0   0.28"/>
      <inertia ixx="0.226891" ixy="0" ixz="0" iyy="0.226891" iyz="0" izz="0.0151074"/>
    </inertial>
    <collision name="UR1_upper_arm_link_collision">
      <origin rpy="0 0 0" xyz="0 0 0"/>
      <geometry>
        <mesh filename="model://ur5/meshes/ur5/collision/upperarm.stl" scale="1 1 1"/>
      </geometry>
    </collision>
    <visual name="UR1_upper_arm_link_visual">
      <origin rpy="0 0 0" xyz="0 0 0"/>
      <geometry>
        <mesh filename="model://ur5/meshes/ur5/visual/upperarm.dae" scale="1 1 1"/>
      </geometry>
    </visual>
  </link>
  <link name="UR1_wrist_1_link">
    <inertial>
      <mass value="1.219"/>
      <origin rpy="0 0 0" xyz="0 0 0"/>
      <inertia ixx="0.111173" ixy="0" ixz="0" iyy="0.111173" iyz="0" izz="0.21942"/>
    </inertial>
    <collision name="UR1_wrist_1_link_collision">
      <origin rpy="0 0 0" xyz="0 0 0"/>
      <geometry>
        <mesh filename="model://ur5/meshes/ur5/collision/wrist1.stl" scale="1 1 1"/>
      </geometry>
    </collision>
    <visual name="UR1_wrist_1_link_visual">
      <origin rpy="0 0 0" xyz="0 0 0"/>
      <geometry>
        <mesh filename="model://ur5/meshes/ur5/visual/wrist1.dae" scale="1 1 1"/>
      </geometry>
    </visual>
  </link>
  <link name="UR1_wrist_2_link">
    <inertial>
      <mass value="1.219"/>
      <origin rpy="0 0 0" xyz="0 0 0"/>
      <inertia ixx="0.111173" ixy="0" ixz="0" iyy="0.111173" iyz="0" izz="0.21942"/>
    </inertial>
    <collision name="UR1_wrist_2_link_collision">
      <origin rpy="0 0 0" xyz="0 0 0"/>
      <geometry>
        <mesh filename="model://ur5/meshes/ur5/collision/wrist2.stl" scale="1 1 1"/>
      </geometry>
    </collision>
    <visual name="UR1_wrist_2_link_visual">
      <origin rpy="0 0 0" xyz="0 0 0"/>
      <geometry>
        <mesh filename="model://ur5/meshes/ur5/visual/wrist2.dae" scale="1 1 1"/>
      </geometry>
    </visual>
  </link>
  <link name="UR1_wrist_3_link">
    <inertial>
      <mass value="0.18791"/>
      <origin rpy="0 0 0" xyz="0 0 0"/>
      <inertia ixx="0.0171375" ixy="6.10083e-20" ixz="5.38596e-20" iyy="0.0171375" iyz="-3.42632e-08" izz="0.033823"/>
    </inertial>
    <collision name="UR1_wrist_3_link_collision">
      <origin rpy="0 0 0" xyz="0 0 0"/>
      <geometry>
        <mesh filename="model://ur5/meshes/ur5/collision/wrist3.stl" scale="1 1 1"/>
      </geometry>
    </collision>
    <visual name="UR1_wrist_3_link_visual">
      <origin rpy="0 0 0" xyz="0 0 0"/>
      <geometry>
        <mesh filename="model://ur5/meshes/ur5/visual/wrist3.dae" scale="1 1 1"/>
      </geometry>
    </visual>
  </link>

  <!-- UR2 part -->
  <joint name="UR2_elbow_joint" type="revolute">
    <parent link="UR2_upper_arm_link"/>
    <child link="UR2_forearm_link"/>
    <origin rpy="0 0 0" xyz="0     -0.1197  0.425"/>
    <axis xyz="0 1 0"/>
    <limit effort="150.0" lower="-3.14159" upper="3.14159" velocity="3.15"/>
  </joint>
  <joint name="UR2_pedestal_JOINT_1" type="fixed">
    <parent link="UR2_pedestal"/>
    <child link="UR2_base_link"/>
    <origin rpy="0 0 0" xyz="0 0 0"/>
    <axis xyz="0 0 0"/>
    <limit effort="0" lower="0" upper="0" velocity="0"/>
  </joint>
  <joint name="UR2_shoulder_lift_joint" type="revolute">
    <parent link="UR2_shoulder_link"/>
    <child link="UR2_upper_arm_link"/>
    <origin rpy="3.14148 1.57079 3.14148" xyz="0      0.13585 0"/>
    <axis xyz="0 1 0"/>
    <limit effort="150.0" lower="-6.28319" upper="6.28319" velocity="3.15"/>
  </joint>
  <joint name="UR2_shoulder_pan_joint" type="revolute">
    <parent link="UR2_base_link"/>
    <child link="UR2_shoulder_link"/>
    <origin rpy="0 0 0" xyz="0      0      0.08915"/>
    <axis xyz="0 0 1"/>
    <limit effort="150.0" lower="-6.28319" upper="6.28319" velocity="3.15"/>
  </joint>
  <joint name="UR2_wrist_1_joint" type="revolute">
    <parent link="UR2_forearm_link"/>
    <child link="UR2_wrist_1_link"/>
    <origin rpy="0.39713 1.57078 0.39713" xyz="0      0      0.39225"/>
    <axis xyz="0 1 0"/>
    <limit effort="28.0" lower="-6.28319" upper="6.28319" velocity="3.2"/>
  </joint>
  <joint name="UR2_wrist_2_joint" type="revolute">
    <parent link="UR2_wrist_1_link"/>
    <child link="UR2_wrist_2_link"/>
    <origin rpy="0 0 0" xyz="0    0.093 0"/>
    <axis xyz="0 0 1"/>
    <limit effort="28.0" lower="-6.28319" upper="6.28319" velocity="3.2"/>
  </joint>
  <joint name="UR2_wrist_3_joint" type="revolute">
    <parent link="UR2_wrist_2_link"/>
    <child link="UR2_wrist_3_link"/>
    <origin rpy="0 0 0" xyz="0      0      0.09465"/>
    <axis xyz="0 1 0"/>
    <limit effort="28.0" lower="-6.28319" upper="6.28319" velocity="3.2"/>
  </joint>
  <link name="UR2_base_link">
    <inertial>
      <mass value="4"/>
      <origin rpy="0 0 0" xyz="0 0 0"/>
      <inertia ixx="0.00443333" ixy="0" ixz="0" iyy="0.00443333" iyz="0" izz="0.0072"/>
    </inertial>
    <collision name="UR2_base_link_collision">
      <origin rpy="0 0 0" xyz="0 0 0"/>
      <geometry>
        <mesh filename="model://ur5/meshes/ur5/collision/base.stl" scale="1 1 1"/>
      </geometry>
    </collision>
    <visual name="UR2_base_link_visual">
      <origin rpy="0 0 0" xyz="0 0 0"/>
      <geometry>
        <mesh filename="model://ur5/meshes/ur5/visual/base.dae" scale="1 1 1"/>
      </geometry>
    </visual>
  </link>
  <link name="UR2_forearm_link">
    <inertial>
      <mass value="2.275"/>
      <origin rpy="0 0 0" xyz="0   0   0.25"/>
      <inertia ixx="0.0494433" ixy="0" ixz="0" iyy="0.0494433" iyz="0" izz="0.004095"/>
    </inertial>
    <collision name="UR2_forearm_link_collision">
      <origin rpy="0 0 0" xyz="0 0 0"/>
      <geometry>
        <mesh filename="model://ur5/meshes/ur5/collision/forearm.stl" scale="1 1 1"/>
      </geometry>
    </collision>
    <visual name="UR2_forearm_link_visual">
      <origin rpy="0 0 0" xyz="0 0 0"/>
      <geometry>
        <mesh filename="model://ur5/meshes/ur5/visual/forearm.dae" scale="1 1 1"/>
      </geometry>
    </visual>
  </link>
  <link name="UR2_pedestal">
    <inertial>
      <mass value="1"/>
      <origin rpy="0 0 0" xyz="0 0 0"/>
      <inertia ixx="0.145833" ixy="0" ixz="0" iyy="0.145833" iyz="0" izz="0.125"/>
    </inertial>
<!--     <collision name="UR2_collision">
      <origin rpy="-2.0e-05  1.4e-04  0.0e+00" xyz="0   0  -0.5"/>
      <geometry>
        <cylinder length="1" radius="0.15"/>
      </geometry>
    </collision> -->
    <visual name="UR2_visual">
      <origin rpy="-2.0e-05  1.4e-04  0.0e+00" xyz="0   0  -0.5"/>
      <geometry>
        <cylinder length="1" radius="0.15"/>
      </geometry>
    </visual>
  </link>
  <link name="UR2_shoulder_link">
    <inertial>
      <mass value="3.7"/>
      <origin rpy="0 0 0" xyz="0 0 0"/>
      <inertia ixx="0.0102675" ixy="0" ixz="0" iyy="0.0102675" iyz="0" izz="0.00666"/>
    </inertial>
    <collision name="UR2_shoulder_link_collision">
      <origin rpy="0 0 0" xyz="0 0 0"/>
      <geometry>
        <mesh filename="model://ur5/meshes/ur5/collision/shoulder.stl" scale="1 1 1"/>
      </geometry>
    </collision>
    <visual name="UR2_shoulder_link_visual">
      <origin rpy="0 0 0" xyz="0 0 0"/>
      <geometry>
        <mesh filename="model://ur5/meshes/ur5/visual/shoulder.dae" scale="1 1 1"/>
      </geometry>
    </visual>
  </link>
  <link name="UR2_upper_arm_link">
    <inertial>
      <mass value="8.393"/>
      <origin rpy="0 0 0" xyz="0   0   0.28"/>
      <inertia ixx="0.226891" ixy="0" ixz="0" iyy="0.226891" iyz="0" izz="0.0151074"/>
    </inertial>
    <collision name="UR2_upper_arm_link_collision">
      <origin rpy="0 0 0" xyz="0 0 0"/>
      <geometry>
        <mesh filename="model://ur5/meshes/ur5/collision/upperarm.stl" scale="1 1 1"/>
      </geometry>
    </collision>
    <visual name="UR2_upper_arm_link_visual">
      <origin rpy="0 0 0" xyz="0 0 0"/>
      <geometry>
        <mesh filename="model://ur5/meshes/ur5/visual/upperarm.dae" scale="1 1 1"/>
      </geometry>
    </visual>
  </link>
  <link name="UR2_wrist_1_link">
    <inertial>
      <mass value="1.219"/>
      <origin rpy="0 0 0" xyz="0 0 0"/>
      <inertia ixx="0.111173" ixy="0" ixz="0" iyy="0.111173" iyz="0" izz="0.21942"/>
    </inertial>
    <collision name="UR2_wrist_1_link_collision">
      <origin rpy="0 0 0" xyz="0 0 0"/>
      <geometry>
        <mesh filename="model://ur5/meshes/ur5/collision/wrist1.stl" scale="1 1 1"/>
      </geometry>
    </collision>
    <visual name="UR2_wrist_1_link_visual">
      <origin rpy="0 0 0" xyz="0 0 0"/>
      <geometry>
        <mesh filename="model://ur5/meshes/ur5/visual/wrist1.dae" scale="1 1 1"/>
      </geometry>
    </visual>
  </link>
  <link name="UR2_wrist_2_link">
    <inertial>
      <mass value="1.219"/>
      <origin rpy="0 0 0" xyz="0 0 0"/>
      <inertia ixx="0.111173" ixy="0" ixz="0" iyy="0.111173" iyz="0" izz="0.21942"/>
    </inertial>
    <collision name="UR2_wrist_2_link_collision">
      <origin rpy="0 0 0" xyz="0 0 0"/>
      <geometry>
        <mesh filename="model://ur5/meshes/ur5/collision/wrist2.stl" scale="1 1 1"/>
      </geometry>
    </collision>
    <visual name="UR2_wrist_2_link_visual">
      <origin rpy="0 0 0" xyz="0 0 0"/>
      <geometry>
        <mesh filename="model://ur5/meshes/ur5/visual/wrist2.dae" scale="1 1 1"/>
      </geometry>
    </visual>
  </link>
  <link name="UR2_wrist_3_link">
    <inertial>
      <mass value="0.18791"/>
      <origin rpy="0 0 0" xyz="0 0 0"/>
      <inertia ixx="0.0171375" ixy="6.10083e-20" ixz="5.38596e-20" iyy="0.0171375" iyz="-3.42632e-08" izz="0.033823"/>
    </inertial>
    <collision name="UR2_wrist_3_link_collision">
      <origin rpy="0 0 0" xyz="0 0 0"/>
      <geometry>
        <mesh filename="model://ur5/meshes/ur5/collision/wrist3.stl" scale="1 1 1"/>
      </geometry>
    </collision>
    <visual name="UR2_wrist_3_link_visual">
      <origin rpy="0 0 0" xyz="0 0 0"/>
      <geometry>
        <mesh filename="model://ur5/meshes/ur5/visual/wrist3.dae" scale="1 1 1"/>
      </geometry>
    </visual>
  </link>

  <!-- UR3 part -->
  <joint name="UR3_elbow_joint" type="revolute">
    <parent link="UR3_upper_arm_link"/>
    <child link="UR3_forearm_link"/>
    <origin rpy="0 0 0" xyz="0     -0.1197  0.425"/>
    <axis xyz="0 1 0"/>
    <limit effort="150.0" lower="-3.14159" upper="3.14159" velocity="3.15"/>
  </joint>
  <joint name="UR3_pedestal_JOINT_1" type="fixed">
    <parent link="UR3_pedestal"/>
    <child link="UR3_base_link"/>
    <origin rpy="0 0 0" xyz="0 0 0"/>
    <axis xyz="0 0 0"/>
    <limit effort="0" lower="0" upper="0" velocity="0"/>
  </joint>
  <joint name="UR3_shoulder_lift_joint" type="revolute">
    <parent link="UR3_shoulder_link"/>
    <child link="UR3_upper_arm_link"/>
    <origin rpy="3.14148 1.57079 3.14148" xyz="0      0.13585 0"/>
    <axis xyz="0 1 0"/>
    <limit effort="150.0" lower="-6.28319" upper="6.28319" velocity="3.15"/>
  </joint>
  <joint name="UR3_shoulder_pan_joint" type="revolute">
    <parent link="UR3_base_link"/>
    <child link="UR3_shoulder_link"/>
    <origin rpy="0 0 0" xyz="0      0      0.08915"/>
    <axis xyz="0 0 1"/>
    <limit effort="150.0" lower="-6.28319" upper="6.28319" velocity="3.15"/>
  </joint>
  <joint name="UR3_wrist_1_joint" type="revolute">
    <parent link="UR3_forearm_link"/>
    <child link="UR3_wrist_1_link"/>
    <origin rpy="0.39713 1.57078 0.39713" xyz="0      0      0.39225"/>
    <axis xyz="0 1 0"/>
    <limit effort="28.0" lower="-6.28319" upper="6.28319" velocity="3.2"/>
  </joint>
  <joint name="UR3_wrist_2_joint" type="revolute">
    <parent link="UR3_wrist_1_link"/>
    <child link="UR3_wrist_2_link"/>
    <origin rpy="0 0 0" xyz="0    0.093 0"/>
    <axis xyz="0 0 1"/>
    <limit effort="28.0" lower="-6.28319" upper="6.28319" velocity="3.2"/>
  </joint>
  <joint name="UR3_wrist_3_joint" type="revolute">
    <parent link="UR3_wrist_2_link"/>
    <child link="UR3_wrist_3_link"/>
    <origin rpy="0 0 0" xyz="0      0      0.09465"/>
    <axis xyz="0 1 0"/>
    <limit effort="28.0" lower="-6.28319" upper="6.28319" velocity="3.2"/>
  </joint>
  <link name="UR3_base_link">
    <inertial>
      <mass value="4"/>
      <origin rpy="0 0 0" xyz="0 0 0"/>
      <inertia ixx="0.00443333" ixy="0" ixz="0" iyy="0.00443333" iyz="0" izz="0.0072"/>
    </inertial>
    <collision name="UR3_base_link_collision">
      <origin rpy="0 0 0" xyz="0 0 0"/>
      <geometry>
        <mesh filename="model://ur5/meshes/ur5/collision/base.stl" scale="1 1 1"/>
      </geometry>
    </collision>
    <visual name="UR3_base_link_visual">
      <origin rpy="0 0 0" xyz="0 0 0"/>
      <geometry>
        <mesh filename="model://ur5/meshes/ur5/visual/base.dae" scale="1 1 1"/>
      </geometry>
    </visual>
  </link>
  <link name="UR3_forearm_link">
    <inertial>
      <mass value="2.275"/>
      <origin rpy="0 0 0" xyz="0   0   0.25"/>
      <inertia ixx="0.0494433" ixy="0" ixz="0" iyy="0.0494433" iyz="0" izz="0.004095"/>
    </inertial>
    <collision name="UR3_forearm_link_collision">
      <origin rpy="0 0 0" xyz="0 0 0"/>
      <geometry>
        <mesh filename="model://ur5/meshes/ur5/collision/forearm.stl" scale="1 1 1"/>
      </geometry>
    </collision>
    <visual name="UR3_forearm_link_visual">
      <origin rpy="0 0 0" xyz="0 0 0"/>
      <geometry>
        <mesh filename="model://ur5/meshes/ur5/visual/forearm.dae" scale="1 1 1"/>
      </geometry>
    </visual>
  </link>
  <link name="UR3_pedestal">
    <inertial>
      <mass value="1"/>
      <origin rpy="0 0 0" xyz="0 0 0"/>
      <inertia ixx="0.145833" ixy="0" ixz="0" iyy="0.145833" iyz="0" izz="0.125"/>
    </inertial>
<!--     <collision name="UR3_collision">
      <origin rpy="-2.0e-05  1.4e-04  0.0e+00" xyz="0   0  -0.5"/>
      <geometry>
        <cylinder length="1" radius="0.15"/>
      </geometry>
    </collision> -->
    <visual name="UR3_visual">
      <origin rpy="-2.0e-05  1.4e-04  0.0e+00" xyz="0   0  -0.5"/>
      <geometry>
        <cylinder length="1" radius="0.15"/>
      </geometry>
    </visual>
  </link>
  <link name="UR3_shoulder_link">
    <inertial>
      <mass value="3.7"/>
      <origin rpy="0 0 0" xyz="0 0 0"/>
      <inertia ixx="0.0102675" ixy="0" ixz="0" iyy="0.0102675" iyz="0" izz="0.00666"/>
    </inertial>
    <collision name="UR3_shoulder_link_collision">
      <origin rpy="0 0 0" xyz="0 0 0"/>
      <geometry>
        <mesh filename="model://ur5/meshes/ur5/collision/shoulder.stl" scale="1 1 1"/>
      </geometry>
    </collision>
    <visual name="UR3_shoulder_link_visual">
      <origin rpy="0 0 0" xyz="0 0 0"/>
      <geometry>
        <mesh filename="model://ur5/meshes/ur5/visual/shoulder.dae" scale="1 1 1"/>
      </geometry>
    </visual>
  </link>
  <link name="UR3_upper_arm_link">
    <inertial>
      <mass value="8.393"/>
      <origin rpy="0 0 0" xyz="0   0   0.28"/>
      <inertia ixx="0.226891" ixy="0" ixz="0" iyy="0.226891" iyz="0" izz="0.0151074"/>
    </inertial>
    <collision name="UR3_upper_arm_link_collision">
      <origin rpy="0 0 0" xyz="0 0 0"/>
      <geometry>
        <mesh filename="model://ur5/meshes/ur5/collision/upperarm.stl" scale="1 1 1"/>
      </geometry>
    </collision>
    <visual name="UR3_upper_arm_link_visual">
      <origin rpy="0 0 0" xyz="0 0 0"/>
      <geometry>
        <mesh filename="model://ur5/meshes/ur5/visual/upperarm.dae" scale="1 1 1"/>
      </geometry>
    </visual>
  </link>
  <link name="UR3_wrist_1_link">
    <inertial>
      <mass value="1.219"/>
      <origin rpy="0 0 0" xyz="0 0 0"/>
      <inertia ixx="0.111173" ixy="0" ixz="0" iyy="0.111173" iyz="0" izz="0.21942"/>
    </inertial>
    <collision name="UR3_wrist_1_link_collision">
      <origin rpy="0 0 0" xyz="0 0 0"/>
      <geometry>
        <mesh filename="model://ur5/meshes/ur5/collision/wrist1.stl" scale="1 1 1"/>
      </geometry>
    </collision>
    <visual name="UR3_wrist_1_link_visual">
      <origin rpy="0 0 0" xyz="0 0 0"/>
      <geometry>
        <mesh filename="model://ur5/meshes/ur5/visual/wrist1.dae" scale="1 1 1"/>
      </geometry>
    </visual>
  </link>
  <link name="UR3_wrist_2_link">
    <inertial>
      <mass value="1.219"/>
      <origin rpy="0 0 0" xyz="0 0 0"/>
      <inertia ixx="0.111173" ixy="0" ixz="0" iyy="0.111173" iyz="0" izz="0.21942"/>
    </inertial>
    <collision name="UR3_wrist_2_link_collision">
      <origin rpy="0 0 0" xyz="0 0 0"/>
      <geometry>
        <mesh filename="model://ur5/meshes/ur5/collision/wrist2.stl" scale="1 1 1"/>
      </geometry>
    </collision>
    <visual name="UR3_wrist_2_link_visual">
      <origin rpy="0 0 0" xyz="0 0 0"/>
      <geometry>
        <mesh filename="model://ur5/meshes/ur5/visual/wrist2.dae" scale="1 1 1"/>
      </geometry>
    </visual>
  </link>
  <link name="UR3_wrist_3_link">
    <inertial>
      <mass value="0.18791"/>
      <origin rpy="0 0 0" xyz="0 0 0"/>
      <inertia ixx="0.0171375" ixy="6.10083e-20" ixz="5.38596e-20" iyy="0.0171375" iyz="-3.42632e-08" izz="0.033823"/>
    </inertial>
    <collision name="UR3_wrist_3_link_collision">
      <origin rpy="0 0 0" xyz="0 0 0"/>
      <geometry>
        <mesh filename="model://ur5/meshes/ur5/collision/wrist3.stl" scale="1 1 1"/>
      </geometry>
    </collision>
    <visual name="UR3_wrist_3_link_visual">
      <origin rpy="0 0 0" xyz="0 0 0"/>
      <geometry>
        <mesh filename="model://ur5/meshes/ur5/visual/wrist3.dae" scale="1 1 1"/>
      </geometry>
    </visual>
  </link>

  <!-- UR4 part -->
  <joint name="UR4_elbow_joint" type="revolute">
    <parent link="UR4_upper_arm_link"/>
    <child link="UR4_forearm_link"/>
    <origin rpy="0 0 0" xyz="0     -0.1197  0.425"/>
    <axis xyz="0 1 0"/>
    <limit effort="150.0" lower="-3.14159" upper="3.14159" velocity="3.15"/>
  </joint>
  <joint name="UR4_pedestal_JOINT_1" type="fixed">
    <parent link="UR4_pedestal"/>
    <child link="UR4_base_link"/>
    <origin rpy="0 0 0" xyz="0 0 0"/>
    <axis xyz="0 0 0"/>
    <limit effort="0" lower="0" upper="0" velocity="0"/>
  </joint>
  <joint name="UR4_shoulder_lift_joint" type="revolute">
    <parent link="UR4_shoulder_link"/>
    <child link="UR4_upper_arm_link"/>
    <origin rpy="3.14148 1.57079 3.14148" xyz="0      0.13585 0"/>
    <axis xyz="0 1 0"/>
    <limit effort="150.0" lower="-6.28319" upper="6.28319" velocity="3.15"/>
  </joint>
  <joint name="UR4_shoulder_pan_joint" type="revolute">
    <parent link="UR4_base_link"/>
    <child link="UR4_shoulder_link"/>
    <origin rpy="0 0 0" xyz="0      0      0.08915"/>
    <axis xyz="0 0 1"/>
    <limit effort="150.0" lower="-6.28319" upper="6.28319" velocity="3.15"/>
  </joint>
  <joint name="UR4_wrist_1_joint" type="revolute">
    <parent link="UR4_forearm_link"/>
    <child link="UR4_wrist_1_link"/>
    <origin rpy="0.39713 1.57078 0.39713" xyz="0      0      0.39225"/>
    <axis xyz="0 1 0"/>
    <limit effort="28.0" lower="-6.28319" upper="6.28319" velocity="3.2"/>
  </joint>
  <joint name="UR4_wrist_2_joint" type="revolute">
    <parent link="UR4_wrist_1_link"/>
    <child link="UR4_wrist_2_link"/>
    <origin rpy="0 0 0" xyz="0    0.093 0"/>
    <axis xyz="0 0 1"/>
    <limit effort="28.0" lower="-6.28319" upper="6.28319" velocity="3.2"/>
  </joint>
  <joint name="UR4_wrist_3_joint" type="revolute">
    <parent link="UR4_wrist_2_link"/>
    <child link="UR4_wrist_3_link"/>
    <origin rpy="0 0 0" xyz="0      0      0.09465"/>
    <axis xyz="0 1 0"/>
    <limit effort="28.0" lower="-6.28319" upper="6.28319" velocity="3.2"/>
  </joint>
  <link name="UR4_base_link">
    <inertial>
      <mass value="4"/>
      <origin rpy="0 0 0" xyz="0 0 0"/>
      <inertia ixx="0.00443333" ixy="0" ixz="0" iyy="0.00443333" iyz="0" izz="0.0072"/>
    </inertial>
    <collision name="UR4_base_link_collision">
      <origin rpy="0 0 0" xyz="0 0 0"/>
      <geometry>
        <mesh filename="model://ur5/meshes/ur5/collision/base.stl" scale="1 1 1"/>
      </geometry>
    </collision>
    <visual name="UR4_base_link_visual">
      <origin rpy="0 0 0" xyz="0 0 0"/>
      <geometry>
        <mesh filename="model://ur5/meshes/ur5/visual/base.dae" scale="1 1 1"/>
      </geometry>
    </visual>
  </link>
  <link name="UR4_forearm_link">
    <inertial>
      <mass value="2.275"/>
      <origin rpy="0 0 0" xyz="0   0   0.25"/>
      <inertia ixx="0.0494433" ixy="0" ixz="0" iyy="0.0494433" iyz="0" izz="0.004095"/>
    </inertial>
    <collision name="UR4_forearm_link_collision">
      <origin rpy="0 0 0" xyz="0 0 0"/>
      <geometry>
        <mesh filename="model://ur5/meshes/ur5/collision/forearm.stl" scale="1 1 1"/>
      </geometry>
    </collision>
    <visual name="UR4_forearm_link_visual">
      <origin rpy="0 0 0" xyz="0 0 0"/>
      <geometry>
        <mesh filename="model://ur5/meshes/ur5/visual/forearm.dae" scale="1 1 1"/>
      </geometry>
    </visual>
  </link>
  <link name="UR4_pedestal">
    <inertial>
      <mass value="1"/>
      <origin rpy="0 0 0" xyz="0 0 0"/>
      <inertia ixx="0.145833" ixy="0" ixz="0" iyy="0.145833" iyz="0" izz="0.125"/>
    </inertial>
<!--     <collision name="UR4_collision">
      <origin rpy="-2.0e-05  1.4e-04  0.0e+00" xyz="0   0  -0.5"/>
      <geometry>
        <cylinder length="1" radius="0.15"/>
      </geometry>
    </collision> -->
    <visual name="UR4_visual">
      <origin rpy="-2.0e-05  1.4e-04  0.0e+00" xyz="0   0  -0.5"/>
      <geometry>
        <cylinder length="1" radius="0.15"/>
      </geometry>
    </visual>
  </link>
  <link name="UR4_shoulder_link">
    <inertial>
      <mass value="3.7"/>
      <origin rpy="0 0 0" xyz="0 0 0"/>
      <inertia ixx="0.0102675" ixy="0" ixz="0" iyy="0.0102675" iyz="0" izz="0.00666"/>
    </inertial>
    <collision name="UR4_shoulder_link_collision">
      <origin rpy="0 0 0" xyz="0 0 0"/>
      <geometry>
        <mesh filename="model://ur5/meshes/ur5/collision/shoulder.stl" scale="1 1 1"/>
      </geometry>
    </collision>
    <visual name="UR4_shoulder_link_visual">
      <origin rpy="0 0 0" xyz="0 0 0"/>
      <geometry>
        <mesh filename="model://ur5/meshes/ur5/visual/shoulder.dae" scale="1 1 1"/>
      </geometry>
    </visual>
  </link>
  <link name="UR4_upper_arm_link">
    <inertial>
      <mass value="8.393"/>
      <origin rpy="0 0 0" xyz="0   0   0.28"/>
      <inertia ixx="0.226891" ixy="0" ixz="0" iyy="0.226891" iyz="0" izz="0.0151074"/>
    </inertial>
    <collision name="UR4_upper_arm_link_collision">
      <origin rpy="0 0 0" xyz="0 0 0"/>
      <geometry>
        <mesh filename="model://ur5/meshes/ur5/collision/upperarm.stl" scale="1 1 1"/>
      </geometry>
    </collision>
    <visual name="UR4_upper_arm_link_visual">
      <origin rpy="0 0 0" xyz="0 0 0"/>
      <geometry>
        <mesh filename="model://ur5/meshes/ur5/visual/upperarm.dae" scale="1 1 1"/>
      </geometry>
    </visual>
  </link>
  <link name="UR4_wrist_1_link">
    <inertial>
      <mass value="1.219"/>
      <origin rpy="0 0 0" xyz="0 0 0"/>
      <inertia ixx="0.111173" ixy="0" ixz="0" iyy="0.111173" iyz="0" izz="0.21942"/>
    </inertial>
    <collision name="UR4_wrist_1_link_collision">
      <origin rpy="0 0 0" xyz="0 0 0"/>
      <geometry>
        <mesh filename="model://ur5/meshes/ur5/collision/wrist1.stl" scale="1 1 1"/>
      </geometry>
    </collision>
    <visual name="UR4_wrist_1_link_visual">
      <origin rpy="0 0 0" xyz="0 0 0"/>
      <geometry>
        <mesh filename="model://ur5/meshes/ur5/visual/wrist1.dae" scale="1 1 1"/>
      </geometry>
    </visual>
  </link>
  <link name="UR4_wrist_2_link">
    <inertial>
      <mass value="1.219"/>
      <origin rpy="0 0 0" xyz="0 0 0"/>
      <inertia ixx="0.111173" ixy="0" ixz="0" iyy="0.111173" iyz="0" izz="0.21942"/>
    </inertial>
    <collision name="UR4_wrist_2_link_collision">
      <origin rpy="0 0 0" xyz="0 0 0"/>
      <geometry>
        <mesh filename="model://ur5/meshes/ur5/collision/wrist2.stl" scale="1 1 1"/>
      </geometry>
    </collision>
    <visual name="UR4_wrist_2_link_visual">
      <origin rpy="0 0 0" xyz="0 0 0"/>
      <geometry>
        <mesh filename="model://ur5/meshes/ur5/visual/wrist2.dae" scale="1 1 1"/>
      </geometry>
    </visual>
  </link>
  <link name="UR4_wrist_3_link">
    <inertial>
      <mass value="0.18791"/>
      <origin rpy="0 0 0" xyz="0 0 0"/>
      <inertia ixx="0.0171375" ixy="6.10083e-20" ixz="5.38596e-20" iyy="0.0171375" iyz="-3.42632e-08" izz="0.033823"/>
    </inertial>
    <collision name="UR4_wrist_3_link_collision">
      <origin rpy="0 0 0" xyz="0 0 0"/>
      <geometry>
        <mesh filename="model://ur5/meshes/ur5/collision/wrist3.stl" scale="1 1 1"/>
      </geometry>
    </collision>
    <visual name="UR4_wrist_3_link_visual">
      <origin rpy="0 0 0" xyz="0 0 0"/>
      <geometry>
        <mesh filename="model://ur5/meshes/ur5/visual/wrist3.dae" scale="1 1 1"/>
      </geometry>
    </visual>
  </link>


  <!--ABB part-->
  <joint name="ABB1_joint_1" type="revolute">
    <parent link="ABB1_base_link"/>
    <child link="ABB1_link_1"/>
    <origin rpy="0 0 0" xyz="0     0     0.3991"/>
    <axis xyz="0 0 1"/>
    <limit effort="1000.0" lower="-2.967" upper="2.967" velocity="5.027"/>
  </joint>
  <joint name="ABB1_joint_2" type="revolute">
    <parent link="ABB1_link_1"/>
    <child link="ABB1_link_2"/>
    <origin rpy="0 0 0" xyz="0 0 0"/>
    <axis xyz="0 1 0"/>
    <limit effort="1000.0" lower="-1.745" upper="2.269" velocity="4.189"/>
  </joint>
  <joint name="ABB1_joint_3" type="revolute">
    <parent link="ABB1_link_2"/>
    <child link="ABB1_link_3"/>
    <origin rpy="0 0 0" xyz="0    0    0.448"/>
    <axis xyz="0 1 0"/>
    <limit effort="1000.0" lower="-3.491" upper="1.222" velocity="5.236"/>
  </joint>
  <joint name="ABB1_joint_4" type="revolute">
    <parent link="ABB1_link_3"/>
    <child link="ABB1_link_4"/>
    <origin rpy="0 0 0" xyz="0    0    0.042"/>
    <axis xyz="1 0 0"/>
    <limit effort="1000.0" lower="-4.712" upper="4.712" velocity="6.981"/>
  </joint>
  <joint name="ABB1_joint_5" type="revolute">
    <parent link="ABB1_link_4"/>
    <child link="ABB1_link_5"/>
    <origin rpy="0 0 0" xyz="0.451 0    0"/>
    <axis xyz="0 1 0"/>
    <limit effort="1000.0" lower="-2.269" upper="2.269" velocity="7.069"/>
  </joint>
  <joint name="ABB1_joint_6" type="revolute">
    <parent link="ABB1_link_5"/>
    <child link="ABB1_link_6"/>
    <origin rpy="0 0 0" xyz="0.082 0    0"/>
    <axis xyz="1 0 0"/>
    <limit effort="1000.0" lower="-6.283" upper="6.283" velocity="10.472"/>
  </joint>
  <joint name="ABB1_pedestal_JOINT_0" type="fixed">
    <parent link="ABB1_pedestal"/>
    <child link="ABB1_base_link"/>
    <origin rpy="0 0 0" xyz="0 0 0"/>
    <axis xyz="0 0 0"/>
    <limit effort="0" lower="0" upper="0" velocity="0"/>
  </joint>
  <link name="ABB1_base_link">
    <inertial>
      <mass value="13.7742"/>
      <origin rpy="0 0 0" xyz="-0.02898  0.00059  0.11273"/>
      <inertia ixx="0.101998" ixy="0.000495482" ixz="0.000311158" iyy="0.13969" iyz="-0.000245375" izz="0.130433"/>
    </inertial>
    <collision name="ABB1_base_link_fixed_joint_lump__collision_collision">
      <origin rpy="0 0 0" xyz="0 0 0"/>
      <geometry>
        <mesh filename="model://ABB1200/meshes/collision/base_link.stl" scale="1 1 1"/>
      </geometry>
    </collision>
    <visual name="ABB1_base_link_fixed_joint_lump__visual_visual">
      <origin rpy="0 0 0" xyz="0 0 0"/>
      <geometry>
        <mesh filename="model://ABB1200/meshes/visual/base_link.dae" scale="1 1 1"/>
      </geometry>
    </visual>
  </link>
  <link name="ABB1_pedestal">
    <inertial>
      <mass value="1"/>
      <origin rpy="0 0 0" xyz="0 0 0"/>
      <inertia ixx="0.145833" ixy="0" ixz="0" iyy="0.145833" iyz="0" izz="0.125"/>
    </inertial>
<!--     <collision name="ABB1_collision">
      <origin rpy="0 0 0" xyz="0   0  -0.4"/>
      <geometry>
        <cylinder length="0.9" radius="0.2"/>
      </geometry>
    </collision> -->
    <visual name="ABB1_visual">
      <origin rpy="0 0 0" xyz="0   0  -0.5"/>
      <geometry>
        <cylinder length="1.0" radius="0.2"/>
      </geometry>
    </visual>
  </link>
  <link name="ABB1_link_1">
    <inertial>
      <mass value="11.8419"/>
      <origin rpy="0 0 0" xyz="0.00087 -0.00063 -0.06288"/>
      <inertia ixx="0.11194" ixy="-4.54988e-05" ixz="0.000280961" iyy="0.0915159" iyz="-0.000109905" izz="0.0876456"/>
    </inertial>
    <collision name="ABB1_link_1_fixed_joint_lump__collision_collision">
      <origin rpy="0 0 0" xyz="0 0 0"/>
      <geometry>
        <mesh filename="model://ABB1200/meshes/collision/link_1.stl" scale="1 1 1"/>
      </geometry>
    </collision>
    <visual name="ABB1_link_1_fixed_joint_lump__visual_visual">
      <origin rpy="0 0 0" xyz="0 0 0"/>
      <geometry>
        <mesh filename="model://ABB1200/meshes/visual/link_1.dae" scale="1 1 1"/>
      </geometry>
    </visual>
  </link>
  <link name="ABB1_link_2">
    <inertial>
      <mass value="17.5394"/>
      <origin rpy="0 0 0" xyz="-0.00092 -0.00049  0.25005"/>
      <inertia ixx="0.493558" ixy="1.32136e-05" ixz="0.000209024" iyy="0.462939" iyz="-0.00179901" izz="0.0894214"/>
    </inertial>
    <collision name="ABB1_link_2_fixed_joint_lump__collision_collision">
      <origin rpy="0 0 0" xyz="0 0 0"/>
      <geometry>
        <mesh filename="model://ABB1200/meshes/collision/link_2.stl" scale="1 1 1"/>
      </geometry>
    </collision>
    <visual name="ABB1_link_2_fixed_joint_lump__visual_visual">
      <origin rpy="0 0 0" xyz="0 0 0"/>
      <geometry>
        <mesh filename="model://ABB1200/meshes/visual/link_2.dae" scale="1 1 1"/>
      </geometry>
    </visual>
  </link>
  <link name="ABB1_link_3">
    <inertial>
      <mass value="7.46365"/>
      <origin rpy="0 0 0" xyz="0.09958 0.00114 0.03233"/>
      <inertia ixx="0.0252424" ixy="0.000142737" ixz="-0.00565542" iyy="0.0906438" iyz="0.000142213" izz="0.0825079"/>
    </inertial>
    <collision name="ABB1_link_3_fixed_joint_lump__collision_collision">
      <origin rpy="0 0 0" xyz="0 0 0"/>
      <geometry>
        <mesh filename="model://ABB1200/meshes/collision/link_3.stl" scale="1 1 1"/>
      </geometry>
    </collision>
    <visual name="ABB1_link_3_fixed_joint_lump__visual_visual">
      <origin rpy="0 0 0" xyz="0 0 0"/>
      <geometry>
        <mesh filename="model://ABB1200/meshes/visual/link_3.dae" scale="1 1 1"/>
      </geometry>
    </visual>
  </link>
  <link name="ABB1_link_4">
    <inertial>
      <mass value="2.74436"/>
      <origin rpy="0 0 0" xyz="0.38167 0.00126 0.00516"/>
      <inertia ixx="0.00573099" ixy="-0.000131119" ixz="0.000380232" iyy="0.0118352" iyz="-2.26565e-05" izz="0.0114428"/>
    </inertial>
    <collision name="ABB1_link_4_fixed_joint_lump__collision_collision">
      <origin rpy="0 0 0" xyz="0 0 0"/>
      <geometry>
        <mesh filename="model://ABB1200/meshes/collision/link_4.stl" scale="1 1 1"/>
      </geometry>
    </collision>
    <visual name="ABB1_link_4_fixed_joint_lump__visual_visual">
      <origin rpy="0 0 0" xyz="0 0 0"/>
      <geometry>
        <mesh filename="model://ABB1200/meshes/visual/link_4.dae" scale="1 1 1"/>
      </geometry>
    </visual>
  </link>
  <link name="ABB1_link_5">
    <inertial>
      <mass value="0.62953"/>
      <origin rpy="0 0 0" xyz="0.01119 -0.00105  0.0001"/>
      <inertia ixx="0.000502815" ixy="-1.03173e-05" ixz="-8.74347e-08" iyy="0.00108856" iyz="2.07657e-07" izz="0.000918873"/>
    </inertial>
    <collision name="ABB1_link_5_fixed_joint_lump__collision_collision">
      <origin rpy="0 0 0" xyz="0 0 0"/>
      <geometry>
        <mesh filename="model://ABB1200/meshes/collision/link_5.stl" scale="1 1 1"/>
      </geometry>
    </collision>
    <visual name="ABB1_link_5_fixed_joint_lump__visual_visual">
      <origin rpy="0 0 0" xyz="0 0 0"/>
      <geometry>
        <mesh filename="model://ABB1200/meshes/visual/link_5.dae" scale="1 1 1"/>
      </geometry>
    </visual>
  </link>
  <link name="ABB1_link_6">
    <inertial>
      <mass value="0.137"/>
      <origin rpy="0 0 0" xyz="-0.00706 -0.00017  0"/>
      <inertia ixx="0.001" ixy="0" ixz="0" iyy="0.001" iyz="0" izz="0.001"/>
    </inertial>
    <collision name="ABB1_link_6_fixed_joint_lump__collision_collision">
      <origin rpy="0 0 0" xyz="0 0 0"/>
      <geometry>
        <mesh filename="model://ABB1200/meshes/collision/link_6.stl" scale="1 1 1"/>
      </geometry>
    </collision>
    <visual name="ABB1_link_6_fixed_joint_lump__visual_visual">
      <origin rpy="0 0 0" xyz="0 0 0"/>
      <geometry>
        <mesh filename="model://ABB1200/meshes/visual/link_6.dae" scale="1 1 1"/>
      </geometry>
    </visual>
  </link>

  <!-- ABB2 part -->
  <joint name="ABB2_joint_1" type="revolute">
    <parent link="ABB2_base_link"/>
    <child link="ABB2_link_1"/>
    <origin rpy="0 0 0" xyz="0     0     0.3991"/>
    <axis xyz="0 0 1"/>
    <limit effort="1000.0" lower="-2.967" upper="2.967" velocity="5.027"/>
  </joint>
  <joint name="ABB2_joint_2" type="revolute">
    <parent link="ABB2_link_1"/>
    <child link="ABB2_link_2"/>
    <origin rpy="0 0 0" xyz="0 0 0"/>
    <axis xyz="0 1 0"/>
    <limit effort="1000.0" lower="-1.745" upper="2.269" velocity="4.189"/>
  </joint>
  <joint name="ABB2_joint_3" type="revolute">
    <parent link="ABB2_link_2"/>
    <child link="ABB2_link_3"/>
    <origin rpy="0 0 0" xyz="0    0    0.448"/>
    <axis xyz="0 1 0"/>
    <limit effort="1000.0" lower="-3.491" upper="1.222" velocity="5.236"/>
  </joint>
  <joint name="ABB2_joint_4" type="revolute">
    <parent link="ABB2_link_3"/>
    <child link="ABB2_link_4"/>
    <origin rpy="0 0 0" xyz="0    0    0.042"/>
    <axis xyz="1 0 0"/>
    <limit effort="1000.0" lower="-4.712" upper="4.712" velocity="6.981"/>
  </joint>
  <joint name="ABB2_joint_5" type="revolute">
    <parent link="ABB2_link_4"/>
    <child link="ABB2_link_5"/>
    <origin rpy="0 0 0" xyz="0.451 0    0"/>
    <axis xyz="0 1 0"/>
    <limit effort="1000.0" lower="-2.269" upper="2.269" velocity="7.069"/>
  </joint>
  <joint name="ABB2_joint_6" type="revolute">
    <parent link="ABB2_link_5"/>
    <child link="ABB2_link_6"/>
    <origin rpy="0 0 0" xyz="0.082 0    0"/>
    <axis xyz="1 0 0"/>
    <limit effort="1000.0" lower="-6.283" upper="6.283" velocity="10.472"/>
  </joint>
  <joint name="ABB2_pedestal_JOINT_0" type="fixed">
    <parent link="ABB2_pedestal"/>
    <child link="ABB2_base_link"/>
    <origin rpy="0 0 0" xyz="0 0 0"/>
    <axis xyz="0 0 0"/>
    <limit effort="0" lower="0" upper="0" velocity="0"/>
  </joint>
  <link name="ABB2_base_link">
    <inertial>
      <mass value="13.7742"/>
      <origin rpy="0 0 0" xyz="-0.02898  0.00059  0.11273"/>
      <inertia ixx="0.101998" ixy="0.000495482" ixz="0.000311158" iyy="0.13969" iyz="-0.000245375" izz="0.130433"/>
    </inertial>
    <collision name="ABB2_base_link_fixed_joint_lump__collision_collision">
      <origin rpy="0 0 0" xyz="0 0 0"/>
      <geometry>
        <mesh filename="model://ABB1200/meshes/collision/base_link.stl" scale="1 1 1"/>
      </geometry>
    </collision>
    <visual name="ABB2_base_link_fixed_joint_lump__visual_visual">
      <origin rpy="0 0 0" xyz="0 0 0"/>
      <geometry>
        <mesh filename="model://ABB1200/meshes/visual/base_link.dae" scale="1 1 1"/>
      </geometry>
    </visual>
  </link>
  <link name="ABB2_pedestal">
    <inertial>
      <mass value="1"/>
      <origin rpy="0 0 0" xyz="0 0 0"/>
      <inertia ixx="0.145833" ixy="0" ixz="0" iyy="0.145833" iyz="0" izz="0.125"/>
    </inertial>
<!--     <collision name="ABB2_collision">
      <origin rpy="0 0 0" xyz="0   0  -0.4"/>
      <geometry>
        <cylinder length="0.9" radius="0.2"/>
      </geometry>
    </collision> -->
    <visual name="ABB2_visual">
      <origin rpy="0 0 0" xyz="0   0  -0.5"/>
      <geometry>
        <cylinder length="1.0" radius="0.2"/>
      </geometry>
    </visual>
  </link>
  <link name="ABB2_link_1">
    <inertial>
      <mass value="11.8419"/>
      <origin rpy="0 0 0" xyz="0.00087 -0.00063 -0.06288"/>
      <inertia ixx="0.11194" ixy="-4.54988e-05" ixz="0.000280961" iyy="0.0915159" iyz="-0.000109905" izz="0.0876456"/>
    </inertial>
    <collision name="ABB2_link_1_fixed_joint_lump__collision_collision">
      <origin rpy="0 0 0" xyz="0 0 0"/>
      <geometry>
        <mesh filename="model://ABB1200/meshes/collision/link_1.stl" scale="1 1 1"/>
      </geometry>
    </collision>
    <visual name="ABB2_link_1_fixed_joint_lump__visual_visual">
      <origin rpy="0 0 0" xyz="0 0 0"/>
      <geometry>
        <mesh filename="model://ABB1200/meshes/visual/link_1.dae" scale="1 1 1"/>
      </geometry>
    </visual>
  </link>
  <link name="ABB2_link_2">
    <inertial>
      <mass value="17.5394"/>
      <origin rpy="0 0 0" xyz="-0.00092 -0.00049  0.25005"/>
      <inertia ixx="0.493558" ixy="1.32136e-05" ixz="0.000209024" iyy="0.462939" iyz="-0.00179901" izz="0.0894214"/>
    </inertial>
    <collision name="ABB2_link_2_fixed_joint_lump__collision_collision">
      <origin rpy="0 0 0" xyz="0 0 0"/>
      <geometry>
        <mesh filename="model://ABB1200/meshes/collision/link_2.stl" scale="1 1 1"/>
      </geometry>
    </collision>
    <visual name="ABB2_link_2_fixed_joint_lump__visual_visual">
      <origin rpy="0 0 0" xyz="0 0 0"/>
      <geometry>
        <mesh filename="model://ABB1200/meshes/visual/link_2.dae" scale="1 1 1"/>
      </geometry>
    </visual>
  </link>
  <link name="ABB2_link_3">
    <inertial>
      <mass value="7.46365"/>
      <origin rpy="0 0 0" xyz="0.09958 0.00114 0.03233"/>
      <inertia ixx="0.0252424" ixy="0.000142737" ixz="-0.00565542" iyy="0.0906438" iyz="0.000142213" izz="0.0825079"/>
    </inertial>
    <collision name="ABB2_link_3_fixed_joint_lump__collision_collision">
      <origin rpy="0 0 0" xyz="0 0 0"/>
      <geometry>
        <mesh filename="model://ABB1200/meshes/collision/link_3.stl" scale="1 1 1"/>
      </geometry>
    </collision>
    <visual name="ABB2_link_3_fixed_joint_lump__visual_visual">
      <origin rpy="0 0 0" xyz="0 0 0"/>
      <geometry>
        <mesh filename="model://ABB1200/meshes/visual/link_3.dae" scale="1 1 1"/>
      </geometry>
    </visual>
  </link>
  <link name="ABB2_link_4">
    <inertial>
      <mass value="2.74436"/>
      <origin rpy="0 0 0" xyz="0.38167 0.00126 0.00516"/>
      <inertia ixx="0.00573099" ixy="-0.000131119" ixz="0.000380232" iyy="0.0118352" iyz="-2.26565e-05" izz="0.0114428"/>
    </inertial>
    <collision name="ABB2_link_4_fixed_joint_lump__collision_collision">
      <origin rpy="0 0 0" xyz="0 0 0"/>
      <geometry>
        <mesh filename="model://ABB1200/meshes/collision/link_4.stl" scale="1 1 1"/>
      </geometry>
    </collision>
    <visual name="ABB2_link_4_fixed_joint_lump__visual_visual">
      <origin rpy="0 0 0" xyz="0 0 0"/>
      <geometry>
        <mesh filename="model://ABB1200/meshes/visual/link_4.dae" scale="1 1 1"/>
      </geometry>
    </visual>
  </link>
  <link name="ABB2_link_5">
    <inertial>
      <mass value="0.62953"/>
      <origin rpy="0 0 0" xyz="0.01119 -0.00105  0.0001"/>
      <inertia ixx="0.000502815" ixy="-1.03173e-05" ixz="-8.74347e-08" iyy="0.00108856" iyz="2.07657e-07" izz="0.000918873"/>
    </inertial>
    <collision name="ABB2_link_5_fixed_joint_lump__collision_collision">
      <origin rpy="0 0 0" xyz="0 0 0"/>
      <geometry>
        <mesh filename="model://ABB1200/meshes/collision/link_5.stl" scale="1 1 1"/>
      </geometry>
    </collision>
    <visual name="ABB2_link_5_fixed_joint_lump__visual_visual">
      <origin rpy="0 0 0" xyz="0 0 0"/>
      <geometry>
        <mesh filename="model://ABB1200/meshes/visual/link_5.dae" scale="1 1 1"/>
      </geometry>
    </visual>
  </link>
  <link name="ABB2_link_6">
    <inertial>
      <mass value="0.137"/>
      <origin rpy="0 0 0" xyz="-0.00706 -0.00017  0"/>
      <inertia ixx="0.001" ixy="0" ixz="0" iyy="0.001" iyz="0" izz="0.001"/>
    </inertial>
    <collision name="ABB2_link_6_fixed_joint_lump__collision_collision">
      <origin rpy="0 0 0" xyz="0 0 0"/>
      <geometry>
        <mesh filename="model://ABB1200/meshes/collision/link_6.stl" scale="1 1 1"/>
      </geometry>
    </collision>
    <visual name="ABB2_link_6_fixed_joint_lump__visual_visual">
      <origin rpy="0 0 0" xyz="0 0 0"/>
      <geometry>
        <mesh filename="model://ABB1200/meshes/visual/link_6.dae" scale="1 1 1"/>
      </geometry>
    </visual>
  </link>
  <!-- ABB3 part -->

  <joint name="ABB3_joint_1" type="revolute">
    <parent link="ABB3_base_link"/>
    <child link="ABB3_link_1"/>
    <origin rpy="0 0 0" xyz="0     0     0.3991"/>
    <axis xyz="0 0 1"/>
    <limit effort="1000.0" lower="-2.967" upper="2.967" velocity="5.027"/>
  </joint>
  <joint name="ABB3_joint_2" type="revolute">
    <parent link="ABB3_link_1"/>
    <child link="ABB3_link_2"/>
    <origin rpy="0 0 0" xyz="0 0 0"/>
    <axis xyz="0 1 0"/>
    <limit effort="1000.0" lower="-1.745" upper="2.269" velocity="4.189"/>
  </joint>
  <joint name="ABB3_joint_3" type="revolute">
    <parent link="ABB3_link_2"/>
    <child link="ABB3_link_3"/>
    <origin rpy="0 0 0" xyz="0    0    0.448"/>
    <axis xyz="0 1 0"/>
    <limit effort="1000.0" lower="-3.491" upper="1.222" velocity="5.236"/>
  </joint>
  <joint name="ABB3_joint_4" type="revolute">
    <parent link="ABB3_link_3"/>
    <child link="ABB3_link_4"/>
    <origin rpy="0 0 0" xyz="0    0    0.042"/>
    <axis xyz="1 0 0"/>
    <limit effort="1000.0" lower="-4.712" upper="4.712" velocity="6.981"/>
  </joint>
  <joint name="ABB3_joint_5" type="revolute">
    <parent link="ABB3_link_4"/>
    <child link="ABB3_link_5"/>
    <origin rpy="0 0 0" xyz="0.451 0    0"/>
    <axis xyz="0 1 0"/>
    <limit effort="1000.0" lower="-2.269" upper="2.269" velocity="7.069"/>
  </joint>
  <joint name="ABB3_joint_6" type="revolute">
    <parent link="ABB3_link_5"/>
    <child link="ABB3_link_6"/>
    <origin rpy="0 0 0" xyz="0.082 0    0"/>
    <axis xyz="1 0 0"/>
    <limit effort="1000.0" lower="-6.283" upper="6.283" velocity="10.472"/>
  </joint>
  <joint name="ABB3_pedestal_JOINT_0" type="fixed">
    <parent link="ABB3_pedestal"/>
    <child link="ABB3_base_link"/>
    <origin rpy="0 0 0" xyz="0 0 0"/>
    <axis xyz="0 0 0"/>
    <limit effort="0" lower="0" upper="0" velocity="0"/>
  </joint>
  <link name="ABB3_base_link">
    <inertial>
      <mass value="13.7742"/>
      <origin rpy="0 0 0" xyz="-0.02898  0.00059  0.11273"/>
      <inertia ixx="0.101998" ixy="0.000495482" ixz="0.000311158" iyy="0.13969" iyz="-0.000245375" izz="0.130433"/>
    </inertial>
    <collision name="ABB3_base_link_fixed_joint_lump__collision_collision">
      <origin rpy="0 0 0" xyz="0 0 0"/>
      <geometry>
        <mesh filename="model://ABB1200/meshes/collision/base_link.stl" scale="1 1 1"/>
      </geometry>
    </collision>
    <visual name="ABB3_base_link_fixed_joint_lump__visual_visual">
      <origin rpy="0 0 0" xyz="0 0 0"/>
      <geometry>
        <mesh filename="model://ABB1200/meshes/visual/base_link.dae" scale="1 1 1"/>
      </geometry>
    </visual>
  </link>
  <link name="ABB3_pedestal">
    <inertial>
      <mass value="1"/>
      <origin rpy="0 0 0" xyz="0 0 0"/>
      <inertia ixx="0.145833" ixy="0" ixz="0" iyy="0.145833" iyz="0" izz="0.125"/>
    </inertial>
<!--     <collision name="ABB3_collision">
      <origin rpy="0 0 0" xyz="0   0  -0.4"/>
      <geometry>
        <cylinder length="0.9" radius="0.2"/>
      </geometry>
    </collision> -->
    <visual name="ABB3_visual">
      <origin rpy="0 0 0" xyz="0   0  -0.5"/>
      <geometry>
        <cylinder length="1.0" radius="0.2"/>
      </geometry>
    </visual>
  </link>
  <link name="ABB3_link_1">
    <inertial>
      <mass value="11.8419"/>
      <origin rpy="0 0 0" xyz="0.00087 -0.00063 -0.06288"/>
      <inertia ixx="0.11194" ixy="-4.54988e-05" ixz="0.000280961" iyy="0.0915159" iyz="-0.000109905" izz="0.0876456"/>
    </inertial>
    <collision name="ABB3_link_1_fixed_joint_lump__collision_collision">
      <origin rpy="0 0 0" xyz="0 0 0"/>
      <geometry>
        <mesh filename="model://ABB1200/meshes/collision/link_1.stl" scale="1 1 1"/>
      </geometry>
    </collision>
    <visual name="ABB3_link_1_fixed_joint_lump__visual_visual">
      <origin rpy="0 0 0" xyz="0 0 0"/>
      <geometry>
        <mesh filename="model://ABB1200/meshes/visual/link_1.dae" scale="1 1 1"/>
      </geometry>
    </visual>
  </link>
  <link name="ABB3_link_2">
    <inertial>
      <mass value="17.5394"/>
      <origin rpy="0 0 0" xyz="-0.00092 -0.00049  0.25005"/>
      <inertia ixx="0.493558" ixy="1.32136e-05" ixz="0.000209024" iyy="0.462939" iyz="-0.00179901" izz="0.0894214"/>
    </inertial>
    <collision name="ABB3_link_2_fixed_joint_lump__collision_collision">
      <origin rpy="0 0 0" xyz="0 0 0"/>
      <geometry>
        <mesh filename="model://ABB1200/meshes/collision/link_2.stl" scale="1 1 1"/>
      </geometry>
    </collision>
    <visual name="ABB3_link_2_fixed_joint_lump__visual_visual">
      <origin rpy="0 0 0" xyz="0 0 0"/>
      <geometry>
        <mesh filename="model://ABB1200/meshes/visual/link_2.dae" scale="1 1 1"/>
      </geometry>
    </visual>
  </link>
  <link name="ABB3_link_3">
    <inertial>
      <mass value="7.46365"/>
      <origin rpy="0 0 0" xyz="0.09958 0.00114 0.03233"/>
      <inertia ixx="0.0252424" ixy="0.000142737" ixz="-0.00565542" iyy="0.0906438" iyz="0.000142213" izz="0.0825079"/>
    </inertial>
    <collision name="ABB3_link_3_fixed_joint_lump__collision_collision">
      <origin rpy="0 0 0" xyz="0 0 0"/>
      <geometry>
        <mesh filename="model://ABB1200/meshes/collision/link_3.stl" scale="1 1 1"/>
      </geometry>
    </collision>
    <visual name="ABB3_link_3_fixed_joint_lump__visual_visual">
      <origin rpy="0 0 0" xyz="0 0 0"/>
      <geometry>
        <mesh filename="model://ABB1200/meshes/visual/link_3.dae" scale="1 1 1"/>
      </geometry>
    </visual>
  </link>
  <link name="ABB3_link_4">
    <inertial>
      <mass value="2.74436"/>
      <origin rpy="0 0 0" xyz="0.38167 0.00126 0.00516"/>
      <inertia ixx="0.00573099" ixy="-0.000131119" ixz="0.000380232" iyy="0.0118352" iyz="-2.26565e-05" izz="0.0114428"/>
    </inertial>
    <collision name="ABB3_link_4_fixed_joint_lump__collision_collision">
      <origin rpy="0 0 0" xyz="0 0 0"/>
      <geometry>
        <mesh filename="model://ABB1200/meshes/collision/link_4.stl" scale="1 1 1"/>
      </geometry>
    </collision>
    <visual name="ABB3_link_4_fixed_joint_lump__visual_visual">
      <origin rpy="0 0 0" xyz="0 0 0"/>
      <geometry>
        <mesh filename="model://ABB1200/meshes/visual/link_4.dae" scale="1 1 1"/>
      </geometry>
    </visual>
  </link>
  <link name="ABB3_link_5">
    <inertial>
      <mass value="0.62953"/>
      <origin rpy="0 0 0" xyz="0.01119 -0.00105  0.0001"/>
      <inertia ixx="0.000502815" ixy="-1.03173e-05" ixz="-8.74347e-08" iyy="0.00108856" iyz="2.07657e-07" izz="0.000918873"/>
    </inertial>
    <collision name="ABB3_link_5_fixed_joint_lump__collision_collision">
      <origin rpy="0 0 0" xyz="0 0 0"/>
      <geometry>
        <mesh filename="model://ABB1200/meshes/collision/link_5.stl" scale="1 1 1"/>
      </geometry>
    </collision>
    <visual name="ABB3_link_5_fixed_joint_lump__visual_visual">
      <origin rpy="0 0 0" xyz="0 0 0"/>
      <geometry>
        <mesh filename="model://ABB1200/meshes/visual/link_5.dae" scale="1 1 1"/>
      </geometry>
    </visual>
  </link>
  <link name="ABB3_link_6">
    <inertial>
      <mass value="0.137"/>
      <origin rpy="0 0 0" xyz="-0.00706 -0.00017  0"/>
      <inertia ixx="0.001" ixy="0" ixz="0" iyy="0.001" iyz="0" izz="0.001"/>
    </inertial>
    <collision name="ABB3_link_6_fixed_joint_lump__collision_collision">
      <origin rpy="0 0 0" xyz="0 0 0"/>
      <geometry>
        <mesh filename="model://ABB1200/meshes/collision/link_6.stl" scale="1 1 1"/>
      </geometry>
    </collision>
    <visual name="ABB3_link_6_fixed_joint_lump__visual_visual">
      <origin rpy="0 0 0" xyz="0 0 0"/>
      <geometry>
        <mesh filename="model://ABB1200/meshes/visual/link_6.dae" scale="1 1 1"/>
      </geometry>
    </visual>
  </link>

  <!-- ABB4 part -->
  <joint name="ABB4_joint_1" type="revolute">
    <parent link="ABB4_base_link"/>
    <child link="ABB4_link_1"/>
    <origin rpy="0 0 0" xyz="0     0     0.3991"/>
    <axis xyz="0 0 1"/>
    <limit effort="1000.0" lower="-2.967" upper="2.967" velocity="5.027"/>
  </joint>
  <joint name="ABB4_joint_2" type="revolute">
    <parent link="ABB4_link_1"/>
    <child link="ABB4_link_2"/>
    <origin rpy="0 0 0" xyz="0 0 0"/>
    <axis xyz="0 1 0"/>
    <limit effort="1000.0" lower="-1.745" upper="2.269" velocity="4.189"/>
  </joint>
  <joint name="ABB4_joint_3" type="revolute">
    <parent link="ABB4_link_2"/>
    <child link="ABB4_link_3"/>
    <origin rpy="0 0 0" xyz="0    0    0.448"/>
    <axis xyz="0 1 0"/>
    <limit effort="1000.0" lower="-3.491" upper="1.222" velocity="5.236"/>
  </joint>
  <joint name="ABB4_joint_4" type="revolute">
    <parent link="ABB4_link_3"/>
    <child link="ABB4_link_4"/>
    <origin rpy="0 0 0" xyz="0    0    0.042"/>
    <axis xyz="1 0 0"/>
    <limit effort="1000.0" lower="-4.712" upper="4.712" velocity="6.981"/>
  </joint>
  <joint name="ABB4_joint_5" type="revolute">
    <parent link="ABB4_link_4"/>
    <child link="ABB4_link_5"/>
    <origin rpy="0 0 0" xyz="0.451 0    0"/>
    <axis xyz="0 1 0"/>
    <limit effort="1000.0" lower="-2.269" upper="2.269" velocity="7.069"/>
  </joint>
  <joint name="ABB4_joint_6" type="revolute">
    <parent link="ABB4_link_5"/>
    <child link="ABB4_link_6"/>
    <origin rpy="0 0 0" xyz="0.082 0    0"/>
    <axis xyz="1 0 0"/>
    <limit effort="1000.0" lower="-6.283" upper="6.283" velocity="10.472"/>
  </joint>
  <joint name="ABB4_pedestal_JOINT_0" type="fixed">
    <parent link="ABB4_pedestal"/>
    <child link="ABB4_base_link"/>
    <origin rpy="0 0 0" xyz="0 0 0"/>
    <axis xyz="0 0 0"/>
    <limit effort="0" lower="0" upper="0" velocity="0"/>
  </joint>
  <link name="ABB4_base_link">
    <inertial>
      <mass value="13.7742"/>
      <origin rpy="0 0 0" xyz="-0.02898  0.00059  0.11273"/>
      <inertia ixx="0.101998" ixy="0.000495482" ixz="0.000311158" iyy="0.13969" iyz="-0.000245375" izz="0.130433"/>
    </inertial>
    <collision name="ABB4_base_link_fixed_joint_lump__collision_collision">
      <origin rpy="0 0 0" xyz="0 0 0"/>
      <geometry>
        <mesh filename="model://ABB1200/meshes/collision/base_link.stl" scale="1 1 1"/>
      </geometry>
    </collision>
    <visual name="ABB4_base_link_fixed_joint_lump__visual_visual">
      <origin rpy="0 0 0" xyz="0 0 0"/>
      <geometry>
        <mesh filename="model://ABB1200/meshes/visual/base_link.dae" scale="1 1 1"/>
      </geometry>
    </visual>
  </link>
  <link name="ABB4_pedestal">
    <inertial>
      <mass value="1"/>
      <origin rpy="0 0 0" xyz="0 0 0"/>
      <inertia ixx="0.145833" ixy="0" ixz="0" iyy="0.145833" iyz="0" izz="0.125"/>
    </inertial>
<!--     <collision name="ABB4_collision">
      <origin rpy="0 0 0" xyz="0   0  -0.4"/>
      <geometry>
        <cylinder length="0.9" radius="0.2"/>
      </geometry>
    </collision> -->
    <visual name="ABB4_visual">
      <origin rpy="0 0 0" xyz="0   0  -0.5"/>
      <geometry>
        <cylinder length="1.0" radius="0.2"/>
      </geometry>
    </visual>
  </link>
  <link name="ABB4_link_1">
    <inertial>
      <mass value="11.8419"/>
      <origin rpy="0 0 0" xyz="0.00087 -0.00063 -0.06288"/>
      <inertia ixx="0.11194" ixy="-4.54988e-05" ixz="0.000280961" iyy="0.0915159" iyz="-0.000109905" izz="0.0876456"/>
    </inertial>
    <collision name="ABB4_link_1_fixed_joint_lump__collision_collision">
      <origin rpy="0 0 0" xyz="0 0 0"/>
      <geometry>
        <mesh filename="model://ABB1200/meshes/collision/link_1.stl" scale="1 1 1"/>
      </geometry>
    </collision>
    <visual name="ABB4_link_1_fixed_joint_lump__visual_visual">
      <origin rpy="0 0 0" xyz="0 0 0"/>
      <geometry>
        <mesh filename="model://ABB1200/meshes/visual/link_1.dae" scale="1 1 1"/>
      </geometry>
    </visual>
  </link>
  <link name="ABB4_link_2">
    <inertial>
      <mass value="17.5394"/>
      <origin rpy="0 0 0" xyz="-0.00092 -0.00049  0.25005"/>
      <inertia ixx="0.493558" ixy="1.32136e-05" ixz="0.000209024" iyy="0.462939" iyz="-0.00179901" izz="0.0894214"/>
    </inertial>
    <collision name="ABB4_link_2_fixed_joint_lump__collision_collision">
      <origin rpy="0 0 0" xyz="0 0 0"/>
      <geometry>
        <mesh filename="model://ABB1200/meshes/collision/link_2.stl" scale="1 1 1"/>
      </geometry>
    </collision>
    <visual name="ABB4_link_2_fixed_joint_lump__visual_visual">
      <origin rpy="0 0 0" xyz="0 0 0"/>
      <geometry>
        <mesh filename="model://ABB1200/meshes/visual/link_2.dae" scale="1 1 1"/>
      </geometry>
    </visual>
  </link>
  <link name="ABB4_link_3">
    <inertial>
      <mass value="7.46365"/>
      <origin rpy="0 0 0" xyz="0.09958 0.00114 0.03233"/>
      <inertia ixx="0.0252424" ixy="0.000142737" ixz="-0.00565542" iyy="0.0906438" iyz="0.000142213" izz="0.0825079"/>
    </inertial>
    <collision name="ABB4_link_3_fixed_joint_lump__collision_collision">
      <origin rpy="0 0 0" xyz="0 0 0"/>
      <geometry>
        <mesh filename="model://ABB1200/meshes/collision/link_3.stl" scale="1 1 1"/>
      </geometry>
    </collision>
    <visual name="ABB4_link_3_fixed_joint_lump__visual_visual">
      <origin rpy="0 0 0" xyz="0 0 0"/>
      <geometry>
        <mesh filename="model://ABB1200/meshes/visual/link_3.dae" scale="1 1 1"/>
      </geometry>
    </visual>
  </link>
  <link name="ABB4_link_4">
    <inertial>
      <mass value="2.74436"/>
      <origin rpy="0 0 0" xyz="0.38167 0.00126 0.00516"/>
      <inertia ixx="0.00573099" ixy="-0.000131119" ixz="0.000380232" iyy="0.0118352" iyz="-2.26565e-05" izz="0.0114428"/>
    </inertial>
    <collision name="ABB4_link_4_fixed_joint_lump__collision_collision">
      <origin rpy="0 0 0" xyz="0 0 0"/>
      <geometry>
        <mesh filename="model://ABB1200/meshes/collision/link_4.stl" scale="1 1 1"/>
      </geometry>
    </collision>
    <visual name="ABB4_link_4_fixed_joint_lump__visual_visual">
      <origin rpy="0 0 0" xyz="0 0 0"/>
      <geometry>
        <mesh filename="model://ABB1200/meshes/visual/link_4.dae" scale="1 1 1"/>
      </geometry>
    </visual>
  </link>
  <link name="ABB4_link_5">
    <inertial>
      <mass value="0.62953"/>
      <origin rpy="0 0 0" xyz="0.01119 -0.00105  0.0001"/>
      <inertia ixx="0.000502815" ixy="-1.03173e-05" ixz="-8.74347e-08" iyy="0.00108856" iyz="2.07657e-07" izz="0.000918873"/>
    </inertial>
    <collision name="ABB4_link_5_fixed_joint_lump__collision_collision">
      <origin rpy="0 0 0" xyz="0 0 0"/>
      <geometry>
        <mesh filename="model://ABB1200/meshes/collision/link_5.stl" scale="1 1 1"/>
      </geometry>
    </collision>
    <visual name="ABB4_link_5_fixed_joint_lump__visual_visual">
      <origin rpy="0 0 0" xyz="0 0 0"/>
      <geometry>
        <mesh filename="model://ABB1200/meshes/visual/link_5.dae" scale="1 1 1"/>
      </geometry>
    </visual>
  </link>
  <link name="ABB4_link_6">
    <inertial>
      <mass value="0.137"/>
      <origin rpy="0 0 0" xyz="-0.00706 -0.00017  0"/>
      <inertia ixx="0.001" ixy="0" ixz="0" iyy="0.001" iyz="0" izz="0.001"/>
    </inertial>
    <collision name="ABB4_link_6_fixed_joint_lump__collision_collision">
      <origin rpy="0 0 0" xyz="0 0 0"/>
      <geometry>
        <mesh filename="model://ABB1200/meshes/collision/link_6.stl" scale="1 1 1"/>
      </geometry>
    </collision>
    <visual name="ABB4_link_6_fixed_joint_lump__visual_visual">
      <origin rpy="0 0 0" xyz="0 0 0"/>
      <geometry>
        <mesh filename="model://ABB1200/meshes/visual/link_6.dae" scale="1 1 1"/>
      </geometry>
    </visual>
  </link>

</robot>
